Workbook

Sheet Format viral
A1: Format viral của đối thủ có app — no contact, tuần 17–24.10.2026
A2: Số bài / view tính từ tab "Top bài" (bài ≥15K view đã mở xem hook). Cột "Bản Better off" là đề xuất để bàn.
A4: Mã | B4: Format | C4: Cách làm | D4: Hook mẫu (nguyên văn) | E4: App xuất hiện | F4: Bản Better off (đề xuất) | G4: Số bài top | H4: Tổng view | I4: View cao nhất | J4: View TB | K4: Comment TB | L4: Save TB
A5: A | B5: October theory "xác nhận" | C5: Video 10–15 s: mặt (khóc/buồn, nằm giường) + 1 dòng chữ vàng "guys I can confirm the October theory is 100% real" → cầm điện thoại lướt bộ đếm no contact của app (phút/ngày). | D5: guys I can confirm the October theory is 100% real | "october theory": you either fall for someone new or your ex comes back around | E5: Bộ đếm app cầm tay | F5: ✅ dạng slideshow: selfie buồn + hook → ảnh chụp màn hình bộ đếm Better off (+ dòng "only took a month…") | G5: =COUNTIF('Top bài'!$K:$K,A5) | H5: =SUMIF('Top bài'!$K:$K,A5,'Top bài'!$E:$E) | I5: =_xlfn.MAXIFS('Top bài'!$E:$E,'Top bài'!$K:$K,A5) | J5: =IFERROR(AVERAGEIF('Top bài'!$K:$K,A5,'Top bài'!$E:$E),0) | K5: =IFERROR(AVERAGEIF('Top bài'!$K:$K,A5,'Top bài'!$G:$G),0) | L5: =IFERROR(AVERAGEIF('Top bài'!$K:$K,A5,'Top bài'!$H:$H),0)
A6: B | B6: "Do they ever come back?" — hỏi để kéo comment | C6: Mặt + câu hỏi cho "no contact survivors" → bộ đếm app. Comment rất cao (500–926). | D6: no contact survivors, do they ever come back?? | those who survived no contact, did they ever come back? | E6: Bộ đếm app (iPad/điện thoại) | F6: ✅ selfie + câu hỏi → bộ đếm. Ghim comment trả lời bằng persona | G6: =COUNTIF('Top bài'!$K:$K,A6) | H6: =SUMIF('Top bài'!$K:$K,A6,'Top bài'!$E:$E) | I6: =_xlfn.MAXIFS('Top bài'!$E:$E,'Top bài'!$K:$K,A6) | J6: =IFERROR(AVERAGEIF('Top bài'!$K:$K,A6,'Top bài'!$E:$E),0) | K6: =IFERROR(AVERAGEIF('Top bài'!$K:$K,A6,'Top bài'!$G:$G),0) | L6: =IFERROR(AVERAGEIF('Top bài'!$K:$K,A6,'Top bài'!$H:$H),0)
A7: C | B7: Lời nhắn chưa gửi / vẫn còn yêu | C7: Mặt + câu nói kiểu tin nhắn không dám gửi cho ex. Save + share rất cao so với view (bài 157.8K: 3.9K save, 2.9K share). | D7: and for my final act of love, i'll wait for you… | I miss you. You know I can't text you, but if you texted me I'd answer | I didn't want no contact… I wanted to marry you. | E7: Chỉ caption/hashtag app (#closureapp) | F7: ✅ 1–2 slide: selfie + câu nói. Hợp Luna/Chloe (giọng buồn) | G7: =COUNTIF('Top bài'!$K:$K,A7) | H7: =SUMIF('Top bài'!$K:$K,A7,'Top bài'!$E:$E) | I7: =_xlfn.MAXIFS('Top bài'!$E:$E,'Top bài'!$K:$K,A7) | J7: =IFERROR(AVERAGEIF('Top bài'!$K:$K,A7,'Top bài'!$E:$E),0) | K7: =IFERROR(AVERAGEIF('Top bài'!$K:$K,A7,'Top bài'!$G:$G),0) | L7: =IFERROR(AVERAGEIF('Top bài'!$K:$K,A7,'Top bài'!$H:$H),0)
A8: D | B8: Time ladder → "and then this…" → cặp đôi | C8: Slideshow 6–7 ảnh: selfie "1 week / 1 month / 3 months not texting him" → ảnh app → tin nhắn ex "I have missed you so much… can we try again" + "and then this… He finally felt my absence after I got my energy back" → ảnh bóng 2 người. | D8: 1 month no contact | 1 month not texting him → and then this… | E8: Ảnh màn hình app ở giữa | F8: ✅ đúng timeline-twist của mình; thêm slide kết là ảnh bóng/cặp đôi (shared/couple) | G8: =COUNTIF('Top bài'!$K:$K,A8) | H8: =SUMIF('Top bài'!$K:$K,A8,'Top bài'!$E:$E) | I8: =_xlfn.MAXIFS('Top bài'!$E:$E,'Top bài'!$K:$K,A8) | J8: =IFERROR(AVERAGEIF('Top bài'!$K:$K,A8,'Top bài'!$E:$E),0) | K8: =IFERROR(AVERAGEIF('Top bài'!$K:$K,A8,'Top bài'!$G:$G),0) | L8: =IFERROR(AVERAGEIF('Top bài'!$K:$K,A8,'Top bài'!$H:$H),0)
A9: E | B9: "No contact but not unadded, not blocked" | C9: Mặt + 1 dòng "no contact, but not unadded, not blocked" → app. | D9: no contact, but not unadded, not blocked | E9: Bộ đếm app | F9: ✅ 1 slide hook + 1 slide app | G9: =COUNTIF('Top bài'!$K:$K,A9) | H9: =SUMIF('Top bài'!$K:$K,A9,'Top bài'!$E:$E) | I9: =_xlfn.MAXIFS('Top bài'!$E:$E,'Top bài'!$K:$K,A9) | J9: =IFERROR(AVERAGEIF('Top bài'!$K:$K,A9,'Top bài'!$E:$E),0) | K9: =IFERROR(AVERAGEIF('Top bài'!$K:$K,A9,'Top bài'!$G:$G),0) | L9: =IFERROR(AVERAGEIF('Top bài'!$K:$K,A9,'Top bài'!$H:$H),0)
A10: F | B10: November theory / nhớ mùa năm ngoái | C10: Đón trend tháng 11: "November theory is around the corner", "all I can remember is how in love I was last November". | D10: When it's October and you realise the November theory is lowkey around the corner | when it's November next month but all I can remember is how in love I was last November | E10: Bộ đếm app / caption | F10: ✅ chuẩn bị sẵn cho tuần 26.10–01.11 (trend October hết hạn 31.10) | G10: =COUNTIF('Top bài'!$K:$K,A10) | H10: =SUMIF('Top bài'!$K:$K,A10,'Top bài'!$E:$E) | I10: =_xlfn.MAXIFS('Top bài'!$E:$E,'Top bài'!$K:$K,A10) | J10: =IFERROR(AVERAGEIF('Top bài'!$K:$K,A10,'Top bài'!$E:$E),0) | K10: =IFERROR(AVERAGEIF('Top bài'!$K:$K,A10,'Top bài'!$G:$G),0) | L10: =IFERROR(AVERAGEIF('Top bài'!$K:$K,A10,'Top bài'!$H:$H),0)
A11: G | B11: "Reminder: they always come back" | C11: Mặt + "reminder they always come back. always." → app. | D11: reminder they always come back. always. | E11: Bộ đếm app | F11: ✅ nối với timeline-twist "they always come back" đang chạy | G11: =COUNTIF('Top bài'!$K:$K,A11) | H11: =SUMIF('Top bài'!$K:$K,A11,'Top bài'!$E:$E) | I11: =_xlfn.MAXIFS('Top bài'!$E:$E,'Top bài'!$K:$K,A11) | J11: =IFERROR(AVERAGEIF('Top bài'!$K:$K,A11,'Top bài'!$E:$E),0) | K11: =IFERROR(AVERAGEIF('Top bài'!$K:$K,A11,'Top bài'!$G:$G),0) | L11: =IFERROR(AVERAGEIF('Top bài'!$K:$K,A11,'Top bài'!$H:$H),0)
A13: Nhận xét chính
A14: 1. Format A (October theory) cho 2 bài >500K của 2 app khác nhau, cùng một hook. Trend hết hạn 31.10 → chỉ còn ~1 tuần dùng được; tuần sau chuyển sang F (November theory).
A15: 2. Format B (hỏi "do they ever come back?") ra comment cao nhất (500–926/bài). colleen.healing đăng lại cùng hook 4 lần: 99K → 56K → 22K → 18K, đăng lặp thì giảm dần.
A16: 3. Format C (lời nhắn chưa gửi) có tỉ lệ save + share cao nhất (yu.journeyy 157.8K: 3.9K save, 2.9K share) mà không cần bộ đếm app.
A17: 4. Format D (time ladder → ex nhắn lại → cặp đôi) là slideshow ảnh duy nhất đạt >80K → khớp timeline-twist của Better off; thêm slide kết cặp đôi.
A18: 5. Gần như mọi bài viral là video có mặt thật 10–15 s, rồi bộ đếm app. Account Better off chỉ đăng ảnh → làm bản slideshow: selfie + hook → ảnh màn hình bộ đếm Better off.
A19: 6. Closure đang lấn No Contact App: 136 bài / 1.86M view so với 61 bài / 0.86M view trong tuần. Creator Closure đăng 12–17 bài/tuần (2–3 bài/ngày). Nhóm cũ của No Contact App giảm hẳn: Karim 5 bài, teesha 1, krissy 0.

Sheet Top bài
A1: Account | B1: App | C1: Ngày đăng | D1: Loại | E1: View | F1: Like | G1: Comment | H1: Save | I1: Share | J1: Hook trên màn hình | K1: Mã format | L1: Save/1K view | M1: Link
A2: yu.journeyy | B2: Closure | C2: 10-19 | D2: video | E2: 551200 | F2: 115400 | G2: 535 | H2: 5201 | I2: 4486 | J2: guys I can confirm the October theory is 100% real | K2: A | L2: =IF(OR(H2="",E2=0),"",H2/E2*1000) | M2: mở bài
A3: healwith.katara | B3: No Contact App | C3: 10-18 | D3: video | E3: 539300 | F3: 70700 | G3: 609 | H3: 3722 | I3: 1905 | J3: guys I can confirm the October theory is 100% real (khóc trên giường) | K3: A | L3: =IF(OR(H3="",E3=0),"",H3/E3*1000) | M3: mở bài
A4: healingwlexx | B4: Closure | C4: 10-17 | D4: video | E4: 167700 | F4: 26300 | G4: 926 | H4: 1223 | I4: 161 | J4: no contact survivors, do they ever come back?? | K4: B | L4: =IF(OR(H4="",E4=0),"",H4/E4*1000) | M4: mở bài
A5: yu.journeyy | B5: Closure | C5: 10-17 | D5: video | E5: 157800 | F5: 27600 | G5: 54 | H5: 3922 | I5: 2867 | J5: and for my final act of love, i'll wait for you cause i truly want it to be you. i just hope you don't forget im waiting. | K5: C | L5: =IF(OR(H5="",E5=0),"",H5/E5*1000) | M5: mở bài
A6: resetwith.issy | B6: Zero Contact | C6: 10-18 | D6: photo | E6: 152100 | J6: 1 month no contact (time ladder, glow-up selfie) | K6: D | L6: =IF(OR(H6="",E6=0),"",H6/E6*1000) | M6: mở bài
A7: healingwithbellaaa | B7: Closure | C7: 10-19 | D7: video | E7: 127600 | F7: 12200 | G7: 28 | H7: 582 | I7: 292 | J7: guys i can confirm the october theory is 100% real | K7: A | L7: =IF(OR(H7="",E7=0),"",H7/E7*1000) | M7: mở bài
A8: lifewithkayy114 | B8: Closure | C8: 10-21 | D8: video | E8: 109000 | F8: 19700 | G8: 84 | H8: 1114 | I8: 420 | J8: no contact, but not unadded, not blocked | K8: E | L8: =IF(OR(H8="",E8=0),"",H8/E8*1000) | M8: mở bài
A9: yu.journeyy | B9: Closure | C9: 10-17 | D9: video | E9: 105000 | F9: 23900 | G9: 25 | H9: 1190 | I9: 1835 | J9: when it's November next month but all I can remember is how in love I was last November | K9: F | L9: =IF(OR(H9="",E9=0),"",H9/E9*1000) | M9: mở bài
A10: colleen.healing | B10: Closure | C10: 10-20 | D10: video | E10: 99200 | F10: 5961 | G10: 860 | H10: 311 | I10: 37 | J10: no contact survivors, do they come back? | K10: B | L10: =IF(OR(H10="",E10=0),"",H10/E10*1000) | M10: mở bài
A11: resetwith.issy | B11: Zero Contact | C11: 10-17 | D11: video | E11: 83400 | F11: 2961 | G11: 4 | H11: 104 | I11: 38 | J11: When it's October and you realise the November theory is lowkey around the corner | K11: F | L11: =IF(OR(H11="",E11=0),"",H11/E11*1000) | M11: mở bài
A12: resetwith.issy | B12: Zero Contact | C12: 10-23 | D12: photo | E12: 82300 | J12: 1 month not texting him → … → "and then this… He finally felt my absence after I got my energy back" → bóng 2 người | K12: D | L12: =IF(OR(H12="",E12=0),"",H12/E12*1000) | M12: mở bài
A13: karims.journey | B13: No Contact App | C13: 10-19 | D13: video | E13: 65900 | F13: 4292 | G13: 144 | H13: 187 | I13: 33 | J13: those who survived no contact, tell me. did the ever come back? | K13: B | L13: =IF(OR(H13="",E13=0),"",H13/E13*1000) | M13: mở bài
A14: colleen.healing | B14: Closure | C14: 10-21 | D14: video | E14: 56300 | F14: 4321 | G14: 521 | H14: 255 | I14: 10 | J14: those who survived no contact, did they ever come back? | K14: B | L14: =IF(OR(H14="",E14=0),"",H14/E14*1000) | M14: mở bài
A15: yu.journeyy | B15: Closure | C15: 10-20 | D15: video | E15: 31500 | F15: 6105 | G15: 7 | H15: 548 | I15: 382 | J15: I miss you. You know can't text you, but if you texted me I'd answer | K15: C | L15: =IF(OR(H15="",E15=0),"",H15/E15*1000) | M15: mở bài
A16: resetwith.issy | B16: Zero Contact | C16: 10-20 | D16: video | E16: 31300 | F16: 4748 | G16: 39 | H16: 356 | I16: 186 | J16: reminder they always come back. always. | K16: G | L16: =IF(OR(H16="",E16=0),"",H16/E16*1000) | M16: mở bài
A17: healwith.yu | B17: No Contact App | C17: 10-19 | D17: video | E17: 24700 | F17: 6373 | G17: 7 | H17: 698 | I17: 474 | J17: I didn't want no contact... I wanted to marry you. | K17: C | L17: =IF(OR(H17="",E17=0),"",H17/E17*1000) | M17: mở bài
A18: colleen.healing | B18: Closure | C18: 10-22 | D18: video | E18: 21900 | F18: 1388 | G18: 79 | H18: 54 | I18: 5 | J18: those who survived no contact, do they ever come back? | K18: B | L18: =IF(OR(H18="",E18=0),"",H18/E18*1000) | M18: mở bài
A19: colleen.healing | B19: Closure | C19: 10-23 | D19: video | E19: 18200 | F19: 1146 | G19: 71 | H19: 47 | I19: 8 | J19: those who survived no contact, did they ever come back? | K19: B | L19: =IF(OR(H19="",E19=0),"",H19/E19*1000) | M19: mở bài
A20: healingwithteesha | B20: No Contact App | C20: 10-17 | D20: video | E20: 16000 | F20: 2048 | G20: 8 | H20: 118 | I20: 112 | J20: "october theory" you either fall for someone new or your ex comes back around. | K20: A | L20: =IF(OR(H20="",E20=0),"",H20/E20*1000) | M20: mở bài

Sheet Tất cả bài
A1: Account | B1: App | C1: Ngày đăng | D1: Loại | E1: View | F1: Caption | G1: Âm thanh | H1: Mã format | I1: Link
A2: yu.journeyy | B2: Closure | C2: 10-19 | D2: video | E2: 551200 | F2: #fyp #closureapp | G2: Alex’s original sound | H2: A | I2: mở bài
A3: healwith.katara | B3: No Contact App | C3: 10-18 | D3: video | E3: 539300 | F3: Healing with @No Contact App #nocontact #HealingJourney #healing #relationships | G3: appple’s original sound - appple | H3: A | I3: mở bài
A4: healingwlexx | B4: Closure | C4: 10-17 | D4: video | E4: 167700 | F4: the closure app is the best for no contact #fyp #closure #heartbreak #nocontact #breakup | G4: rainexxj’s original sound | H4: B | I4: mở bài
A5: yu.journeyy | B5: Closure | C5: 10-17 | D5: video | E5: 157800 | F5: #fyp #closureapp | G5: avv’s original sound - Yuíi | H5: C | I5: mở bài
A6: resetwith.issy | B6: Zero Contact | C6: 10-18 | D6: photo | E6: 152100 | F6: #silence #nocontact #pinned #boyfriend #glowup | G6: I&E’s Originalton | H6: D | I6: mở bài
A7: healingwithbellaaa | B7: Closure | C7: 10-19 | D7: video | E7: 127600 | F7: thank god for closure lmao #nocontact #boyfriend #octobertheory #ex #breakup | G7: William Johnson’s This Heart Of Mine Is Broke | H7: A | I7: mở bài
A8: lifewithkayy114 | B8: Closure | C8: 10-21 | D8: video | E8: 109000 | F8: Always on the closure app atp #fyp #breakup #situationship #closureapp #relationships | G8: Vinh ♪’s original sound | H8: E | I8: mở bài
A9: yu.journeyy | B9: Closure | C9: 10-17 | D9: video | E9: 105000 | F9: #fyp #closureapp | G9: Olivia Rodrigo’s purple | H9: F | I9: mở bài
A10: colleen.healing | B10: Closure | C10: 10-20 | D10: video | E10: 99200 | F10: the closure app is my fav for no contact #closureapp #heal #ex #breakup #nocontact | G10: Cal Townsend’s A Stranger Now | H10: B | I10: mở bài
A11: resetwith.issy | B11: Zero Contact | C11: 10-17 | D11: video | E11: 83400 | F11: #silence #nocontact #pinned #boyfriend #glowup | G11: Katy Perry’s The One That Got Away | H11: F | I11: mở bài
A12: resetwith.issy | B12: Zero Contact | C12: 10-23 | D12: photo | E12: 82300 | F12: #silence #nocontact #pinned #boyfriend #glowup | G12: CANCIONES’s sonido original | H12: D | I12: mở bài
A13: karims.journey | B13: No Contact App | C13: 10-19 | D13: video | E13: 65900 | F13: Been healing with @No Contact App #nocontact #healingjourney #healing | G13: ròfers | ロフ’s website Rofers.store | H13: B | I13: mở bài
... A16: resetwith.issy | B16: Zero Contact | C16: 10-20 | D16: video | E16: 31300 | F16: #silence #nocontact #pinned #boyfriend #glowup | G16: Kanye West’s Heartless | H16: G | I16: mở bài
A17: yu.journeyy | B17: Closure | C17: 10-17 | D17: video | E17: 26500 | F17: #fyp #closureapp | G17: kenn’s original sound - kenn | I17: mở bài
A18: healwith.yu | B18: No Contact App | C18: 10-19 | D18: video | E18: 24700 | F18: #fyp #nocontact @No Contact App | G18: avv’s original sound - Yuíi | H18: C | I18: mở bài
A19: colleen.healing | B19: Closure | C19: 10-22 | D19: video | E19: 21900 | F19: The closure app is my favorite #closureapp #heal #breakup #nocontact #ex | G19: Pocket Wren’s A Slow Tally of Coins | H19: B | I19: mở bài
A20: colleen.healing | B20: Closure | C20: 10-23 | D20: video | E20: 18200 | F20: this is why I got the app called closure #closureapp #heal #ex #breakup #nocontact | G20: Asil’s الصوت الأصلي | H20: B | I20: mở bài
A21: yu.journeyy | B21: Closure | C21: 10-17 | D21: video | E21: 17300 | F21: #fyp #closureapp | G21: rithu’s about you x mcpdc | I21: mở bài
A22: healwith.katara | B22: No Contact App | C22: 10-23 | D22: video | E22: 16700 | F22: Healing with @No Contact App #healing #nocontact #HealingJourney #relationships #canonevent | G22: appple’s original sound - appple | I22: mở bài
A23: healingwithteesha | B23: No Contact App | C23: 10-17 | D23: video | E23: 16000 | F23: @No Contact App #Relationship #nocontact #ex #breakups #nocontactrule | G23: user25494650873’s original sound | H23: A | I23: mở bài
A24: lifewithkayy114 | B24: Closure | C24: 10-20 | D24: video | E24: 14300 | F24: I wouldn’t be able to get over him without the closure app#fyp #breakup #situationship #closureapp #relationships | G24: amelia⭐️⭐️’s teen | I24: mở bài
A25: kylie.healingjourney | B25: No Contact App | C25: 10-17 | D25: video | E25: 13500 | F25: No contact is the fastest way to get over someone @No Contact App | G25: Alicat music’s Radiohead no surprises | I25: mở bài
A26: colleen.healing | B26: Closure | C26: 10-24 | D26: video | E26: 13300 | F26: the closure app is so good for no contact #closureapp #ex #heal #breakup #nocontact | G26: ￴ ￴ ￴ ￴￴ ￴ ￴ ￴￴￴’s original sound | I26: mở bài
A27: colleen.healing | B27: Closure | C27: 10-18 | D27: video | E27: 12700 | F27: I got the closure app just in case if they don’t #closureapp #heal #breakup #ex #nocontact | G27: William Johnson’s This Heart Of Mine | I27: mở bài
A28: kylie.healingjourney | B28: No Contact App | C28: 10-17 | D28: photo | E28: 12600 | F28: Im using @No Contact App btw | G28: VØRTEX’s original sound | I28: mở bài
A29: resetwith.issy | B29: Zero Contact | C29: 10-19 | D29: video | E29: 11900 | F29: #silence #nocontact #pinned #boyfriend #glowup | G29: Issy | Glow up tips’s original sound | I29: mở bài
A30: healwith.yu | B30: No Contact App | C30: 10-17 | D30: video | E30: 11700 | F30: #fyp #nocontact @No Contact App | G30: el’s original sound | I30: mở bài
A31: healwith.yu | B31: No Contact App | C31: 10-23 | D31: video | E31: 11400 | F31: #fyp #nocontact @No Contact App | G31: Taylor Swift’s dorothea | I31: mở bài
A32: resetwith.issy | B32: Zero Contact | C32: 10-23 | D32: video | E32: 11000 | F32: #silence #nocontact #pinned #boyfriend #glowup | G32: Kanye West’s Heartless | I32: mở bài
A33: healwith.katara | B33: No Contact App | C33: 10-20 | D33: video | E33: 10300 | F33: I feel like Im loosing it fr😭 @No Contact App tracker with me always #nocontact #HealingJourney #girltok #healing #breakupadvice | G33: appple’ | I33: mở bài
A34: haileyshealing | B34: Closure | C34: 10-19 | D34: video | E34: 10200 | F34: closure is the best app rn #closure #breakup #ex #nocontact #breakups | G34: | astroxv |’s som original | I34: mở bài
A35: yu.journeyy | B35: Closure | C35: 10-23 | D35: video | E35: 10000 | F35: #fyp #closureapp | G35: Khal’s original sound - v4skhl | I35: mở bài
A36: kylie.healingjourney | B36: No Contact App | C36: 10-22 | D36: photo | E36: 9400 | F36: My streak’s in @No Contact App | G36: m’s original sound | I36: mở bài
A37: healwith.katara | B37: No Contact App | C37: 10-17 | D37: video | E37: 9328 | F37: Feel like i’m dying over and over again everyday. @No Contact App helping me heal❤️‍🩹🫂 #nocontact #healing #healingjourney #breakupadvice #girltok | I37: mở bài
A38: yu.journeyy | B38: Closure | C38: 10-19 | D38: video | E38: 9261 | F38: #fyp #closureapp | G38: chæ 𖤓’s original sound - chæ 𖤓 | I38: mở bài
A39: healwith.katara | B39: No Contact App | C39: 10-20 | D39: video | E39: 9049 | F39: 💔 @No Contact App tracker #nocontact #healing #HealingJourney #relationships | G39: appple’s original sound - appple | I39: mở bài
A40: karims.journey | B40: No Contact App | C40: 10-18 | D40: video | E40: 8960 | F40: @No Contact App #nocontact #healingjourney #healing | G40: user19384491’s original sound | I40: mở bài
A41: kylie.healingjourney | B41: No Contact App | C41: 10-18 | D41: photo | E41: 8850 | F41: Im using @No Contact App btw | G41: Joseph Henry’s original sound | I41: mở bài
A42: haileyshealing | B42: Closure | C42: 10-23 | D42: video | E42: 8513 | F42: I was only able to move on w the closure app #closure #breakup #ex #nocontact #breakups | G42: The Meek & gone like summer’s Love Is Sti | I42: mở bài
...

Sheet Đối thủ
A1: Account | B1: App | C1: Vai trò | D1: Follower | E1: Tổng like | F1: Số bài 17–24.10 | G1: Tổng view tuần | H1: View cao nhất | I1: View TB/bài | J1: Bio
A2: nocontact.app | B2: No Contact App | C2: Brand | D2: 39.7K | E2: 2.4M | F2: =COUNTIF('Tất cả bài'!$A$2:$A$210,A2) | G2: =SUMIF('Tất cả bài'!$A$2:$A$210,A2,'Tất cả bài'!$E$2:$E$210) | H2: =IF(F2=0,0,_xlfn.MAXIFS('Tất cả bài'!$E$2:$E$210,'Tất cả bài'!$A$2:$A$210,A2)) | I2: =IF(F2=0,0,G2/F2) | J2: The App You Open Instead of Texting Them. Download Now👇
A3: karims.journey | B3: No Contact App | C3: Creator UGC | D3: 8941 | E3: 6M | F3: =COUNTIF('Tất cả bài'!$A$2:$A$210,A3) | G3: =SUMIF('Tất cả bài'!$A$2:$A$210,A3,'Tất cả bài'!$E$2:$E$210) | H3: =IF(F3=0,0,_xlfn.MAXIFS('Tất cả bài'!$E$2:$E$210,'Tất cả bài'!$A$2:$A$210,A3)) | I3: =IF(F3=0,0,G3/F3) | J3: rebuilding after heartbreak 💔
A4: krissy.single.era | B4: No Contact App | C4: Creator UGC | D4: 2493 | E4: 1.9M | F4: =COUNTIF('Tất cả bài'!$A$2:$A$210,A4) | G4: =SUMIF('Tất cả bài'!$A$2:$A$210,A4,'Tất cả bài'!$E$2:$E$210) | H4: =IF(F4=0,0,_xlfn.MAXIFS('Tất cả bài'!$E$2:$E$210,'Tất cả bài'!$A$2:$A$210,A4)) | I4: =IF(F4=0,0,G4/F4) | J4: me, myself & I > toxic attachment 🪻 just a girl in her no contact era 🏹❤️
A5: krissy.healing | B5: No Contact App | C5: Creator UGC | D5: 4132 | E5: 2.5M | F5: =COUNTIF('Tất cả bài'!$A$2:$A$210,A5) | G5: =SUMIF('Tất cả bài'!$A$2:$A$210,A5,'Tất cả bài'!$E$2:$E$210) | H5: =IF(F5=0,0,_xlfn.MAXIFS('Tất cả bài'!$E$2:$E$210,'Tất cả bài'!$A$2:$A$210,A5)) | I5: =IF(F5=0,0,G5/F5) | J5: my no-contact diary 📔 📝 🕰️ my healing journey with @nocontact.app
A6: healingwithteesha | B6: No Contact App | C6: Creator UGC | D6: 1851 | E6: 1.7M | F6: =COUNTIF('Tất cả bài'!$A$2:$A$210,A6) | G6: =SUMIF('Tất cả bài'!$A$2:$A$210,A6,'Tất cả bài'!$E$2:$E$210) | H6: =IF(F6=0,0,_xlfn.MAXIFS('Tất cả bài'!$E$2:$E$210,'Tất cả bài'!$A$2:$A$210,A6)) | I6: =IF(F6=0,0,G6/F6) | J6: Rebuilding myself after heartbreak🤍
A7: healingwithkathie | B7: No Contact App | C7: Creator UGC | D7: 97 | E7: 11.8K | F7: =COUNTIF('Tất cả bài'!$A$2:$A$210,A7) | G7: =SUMIF('Tất cả bài'!$A$2:$A$210,A7,'Tất cả bài'!$E$2:$E$210) | H7: =IF(F7=0,0,_xlfn.MAXIFS('Tất cả bài'!$E$2:$E$210,'Tất cả bài'!$A$2:$A$210,A7)) | I7: =IF(F7=0,0,G7/F7) | J7: Rebuilding after heartbreak ❤️‍🩹
A8: healwith.katara | B8: No Contact App | C8: Creator UGC | D8: 1070 | E8: 760.7K | F8: =COUNTIF('Tất cả bài'!$A$2:$A$210,A8) | G8: =SUMIF('Tất cả bài'!$A$2:$A$210,A8,'Tất cả bài'!$E$2:$E$210) | H8: =IF(F8=0,0,_xlfn.MAXIFS('Tất cả bài'!$E$2:$E$210,'Tất cả bài'!$A$2:$A$210,A8)) | I8: =IF(F8=0,0,G8/F8) | J8: Healing slowly ❤️‍🩹
A9: healwith.yu | B9: No Contact App | C9: Creator UGC | D9: 25 | E9: 36.8K | F9: =COUNTIF('Tất cả bài'!$A$2:$A$210,A9) | G9: =SUMIF('Tất cả bài'!$A$2:$A$210,A9,'Tất cả bài'!$E$2:$E$210) | H9: =IF(F9=0,0,_xlfn.MAXIFS('Tất cả bài'!$E$2:$E$210,'Tất cả bài'!$A$2:$A$210,A9)) | I9: =IF(F9=0,0,G9/F9) | J9: Hi! Come heal with me
A10: hannahnocontact | B10: No Contact App | C10: Creator UGC | D10: 194 | E10: 107.5K | F10: =COUNTIF('Tất cả bài'!$A$2:$A$210,A10) | G10: =SUMIF('Tất cả bài'!$A$2:$A$210,A10,'Tất cả bài'!$E$2:$E$210) | H10: =IF(F10=0,0,_xlfn.MAXIFS('Tất cả bài'!$E$2:$E$210,'Tất cả bài'!$A$2:$A$210,A10)) | I10: =IF(F10=0,0,G10/F10) | J10: Let's heal together. 🥀
A11: resetwith.issy | B11: Zero Contact | C11: Creator UGC | D11: 2860 | E11: 572.6K | F11: =COUNTIF('Tất cả bài'!$A$2:$A$210,A11) | G11: =SUMIF('Tất cả bài'!$A$2:$A$210,A11,'Tất cả bài'!$E$2:$E$210) | H11: =IF(F11=0,0,_xlfn.MAXIFS('Tất cả bài'!$E$2:$E$210,'Tất cả bài'!$A$2:$A$210,A11)) | I11: =IF(F11=0,0,G11/F11) | J11: Time to reset 🍃💛 Zero contact ambassador
A12: kyliiee.movingon | B12: No Contact App | C12: Creator UGC | D12: 1992 | E12: 1.3M | F12: =COUNTIF('Tất cả bài'!$A$2:$A$210,A12) | G12: =SUMIF('Tất cả bài'!$A$2:$A$210,A12,'Tất cả bài'!$E$2:$E$210) | H12: =IF(F12=0,0,_xlfn.MAXIFS('Tất cả bài'!$E$2:$E$210,'Tất cả bài'!$A$2:$A$210,A12)) | I12: =IF(F12=0,0,G12/F12) | J12: Your emotional support bestie Moving on with @No Contact App
A13: kylie.healingjourney | B13: No Contact App | C13: Creator UGC | D13: 450 | E13: 202.8K | F13: =COUNTIF('Tất cả bài'!$A$2:$A$210,A13) | G13: =SUMIF('Tất cả bài'!$A$2:$A$210,A13,'Tất cả bài'!$E$2:$E$210) | H13: =IF(F13=0,0,_xlfn.MAXIFS('Tất cả bài'!$E$2:$E$210,'Tất cả bài'!$A$2:$A$210,A13)) | I13: =IF(F13=0,0,G13/F13) | J13: Healing one day at a time 🤍
... A28: ellaa.clo | B28: Closure | C28: Creator UGC | D28: 319 | E28: 335.8K | F28: =COUNTIF('Tất cả bài'!$A$2:$A$210,A28) | G28: =SUMIF('Tất cả bài'!$A$2:$A$210,A28,'Tất cả bài'!$E$2:$E$210) | H28: =IF(F28=0,0,_xlfn.MAXIFS('Tất cả bài'!$E$2:$E$210,'Tất cả bài'!$A$2:$A$210,A28)) | I28: =IF(F28=0,0,G28/F28) | J28: healing ❤️‍🩹
A30: Theo app
A31: Closure | F31: =SUMIF($B$2:$B$28,A31,$F$2:$F$28) | G31: =SUMIF($B$2:$B$28,A31,$G$2:$G$28)
A32: No Contact App | F32: =SUMIF($B$2:$B$28,A32,$F$2:$F$28) | G32: =SUMIF($B$2:$B$28,A32,$G$2:$G$28)
A33: Zero Contact | F33: =SUMIF($B$2:$B$28,A33,$F$2:$F$28) | G33: =SUMIF($B$2:$B$28,A33,$G$2:$G$28)
A34: Break | F34: =SUMIF($B$2:$B$28,A34,$F$2:$F$28) | G34: =SUMIF($B$2:$B$28,A34,$G$2:$G$28)

Sheet Cách làm
A1: Cách làm (25.10.2026, Chrome, không đăng nhập)
A2: • Tìm trên TikTok: "no contact app", "no contact tracker", "nocontactapp", "zero contact app", "closure app no contact", "#closureapp", "breakup app ex", "october theory no contact", "no contact day counter ex texted".
A3: • Chỉ giữ account có quảng bá app (tag @No Contact App / #closureapp / bio nhắc app, hoặc account brand). Bỏ account cá nhân không chạy app.
A4: • Đã loại: myex.and_i (117K follower, không có app) và manifestbeingher (app manifest Adiel: gần no contact nhưng là app khác mảng; bài top 215.6K view).
A5: • Khoảng thời gian: bài đăng từ 17.10 đến 24.10.2026 (ngày tính theo UTC từ ID bài).
A6: • View đọc ở lưới profile. Like/comment/save/share chỉ đọc cho bài trong tab Top bài (trang video).
A7: • Bài cũ hơn 17.10 có thể vẫn đang lên view nhưng không tính.
A8: • Nghiên cứu trước: research/competitors-no-contact-2026-10-15, research/no-contact-week-2026-10-18.
A9: • Dữ liệu thô: competitors_raw.txt, competitors.json (cùng thư mục).
